Workbook

Sheet SAISIE
A1: Nom du produit | B1: Catégorie | C1: Masse (kg) | D1: Matière 1 | E1: Matière 1 — Part | F1: Matière 1 — Pays | G1: Matière 2 | H1: Matière 2 — Part | I1: Matière 2 — Pays | J1: Matière 3 | K1: Matière 3 — Part | L1: Matière 3 — Pays | M1: Matière 4 | N1: Matière 4 — Part | O1: Matière 4 — Pays | P1: Matière 5 | Q1: Matière 5 — Part | R1: Matière 5 — Pays | S1: Pays Filature | T1: Pays Tissage | U1: Pays Ennoblissement | V1: Pays Confection
A2: Produit Test 001 - Jupe / Robe | B2: Jupe / Robe | C2: 0.39 | D2: Polyester | E2: 1 | F2: Pays inconnu (par défaut) | S2: Région - Amérique Latine | T2: Pays inconnu (par défaut) | U2: Région - Océanie | V2: Région - Asie
A3: Produit Test 002 - Caleçon (tissé) | B3: Caleçon (tissé) | C3: 0.39 | D3: Coton recyclé (déchets de production) | E3: 1 | F3: Myanmar | S3: France | T3: Cambodge | U3: Vietnam | V3: Région - Océanie
A4: Produit Test 003 - Chaussettes | B4: Chaussettes | C4: 0.1 | D4: Viscose | E4: 1 | F4: Inde | S4: Région - Océanie | T4: Région - Afrique | U4: Maroc | V4: France
A5: Produit Test 004 - T-shirt / Polo | B5: T-shirt / Polo | C5: 0.19 | D5: Chanvre | E5: 0.54 | F5: Cambodge | G5: Polyester | H5: 0.46 | I5: Myanmar | S5: Région - Océanie | T5: Tunisie | U5: Région - Amérique Latine | V5: Région - Moyen-Orient
A6: Produit Test 005 - Jean | B6: Jean | C6: 0.7 | D6: Lin | E6: 1 | F6: Bangladesh | S6: Inde | T6: Maroc | U6: Turquie | V6: Turquie
A7: Produit Test 006 - T-shirt / Polo | B7: T-shirt / Polo | C7: 0.17 | D7: Polyester recyclé | E7: 0.74 | F7: Région - Amérique Latine | G7: Coton recyclé (déchets post-consommation) | H7: 0.26 | I7: Région - Océanie | S7: Cambodge | T7: Région - Océanie | U7: France | V7: Région - Amérique du nord
A8: Produit Test 007 - Maillot de bain | B8: Maillot de bain | C8: 0.19 | D8: Polypropylène | E8: 0.56 | F8: Région - Amérique du nord | G8: Coton | H8: 0.44 | I8: Cambodge | S8: Turquie | T8: Région - Afrique | U8: Cambodge | V8: Tunisie
A9: Produit Test 008 - Caleçon (tissé) | B9: Caleçon (tissé) | C9: 0.48 | D9: Coton recyclé (déchets post-consommation) | E9: 0.89 | F9: Région - Amérique du nord | G9: Lin | H9: 0.11 | I9: Chine | S9: Pakistan | T9: Région - Amérique Latine | U9: Myanmar | V9: Vietnam
A10: Produit Test 009 - Manteau / Veste | B10: Manteau / Veste | C10: 0.2 | D10: Polyester recyclé | E10: 1 | F10: France | S10: Bangladesh | T10: Région - Océanie | U10: Turquie | V10: Région - Europe de l'Ouest
A11: Produit Test 010 - Manteau / Veste | B11: Manteau / Veste | C11: 0.34 | D11: Polyester | E11: 1 | F11: Région - Europe de l'Ouest | S11: Vietnam | T11: Myanmar | U11: Chine | V11: Région - Amérique Latine
A12: Produit Test 011 - Pull | B12: Pull | C12: 0.3 | D12: Jute | E12: 1 | F12: Pays inconnu (par défaut) | S12: Région - Océanie | T12: Région - Moyen-Orient | U12: Région - Asie | V12: Pakistan
A13: Produit Test 012 - Maillot de bain | B13: Maillot de bain | C13: 0.22 | D13: Laine nouvelle filière | E13: 1 | F13: Cambodge | S13: Tunisie | T13: Région - Amérique du nord | U13: Région - Moyen-Orient | V13: Région - Asie
A14: Produit Test 013 - Caleçon (tissé) | B14: Caleçon (tissé) | C14: 0.5 | D14: Nylon | E14: 0.87 | F14: Cambodge | G14: Coton | H14: 0.13 | I14: France | S14: Inde | T14: Myanmar | U14: Myanmar | V14: Région - Europe de l'Est
A15: Produit Test 014 - Boxer / Slip (tricoté) | B15: Boxer / Slip (tricoté) | C15: 0.29 | D15: Elasthane | E15: 0.66 | F15: Région - Europe de l'Ouest | G15: Coton | H15: 0.34 | I15: France | S15: Région - Asie | T15: Région - Amérique du nord | U15: Vietnam | V15: Région - Amérique Latine
A16: Produit Test 015 - Pull | B16: Pull | C16: 0.37 | D16: Elasthane | E16: 1 | F16: Pakistan | S16: Vietnam | T16: Région - Amérique du nord | U16: Pays inconnu (par défaut) | V16: Maroc
A17: Produit Test 016 - Jupe / Robe | B17: Jupe / Robe | C17: 0.33 | D17: Coton recyclé (déchets de production) | E17: 0.79 | F17: Pays inconnu (par défaut) | G17: Coton recyclé (déchets post-consommation) | H17: 0.21 | I17: Pays inconnu (par défaut) | S17: Région - Amérique du nord | T17: Chine | U17: Région - Océanie | V17: Région - Océanie
A18: Produit Test 017 - Jean | B18: Jean | C18: 0.73 | D18: Viscose | E18: 0.78 | F18: Région - Europe de l'Ouest | G18: Nylon | H18: 0.22 | I18: Chine | S18: Pays inconnu (par défaut) | T18: Bangladesh | U18: Pays inconnu (par défaut) | V18: Région - Europe de l'Est
A19: Produit Test 018 - Chaussettes | B19: Chaussettes | C19: 0.1 | D19: Polyester recyclé | E19: 0.83 | F19: Turquie | G19: Chanvre | H19: 0.17 | I19: Chine | S19: Région - Moyen-Orient | T19: Myanmar | U19: Région - Océanie | V19: France
A20: Produit Test 019 - Manteau / Veste | B20: Manteau / Veste | C20: 0.37 | D20: Coton recyclé (déchets post-consommation) | E20: 1 | F20: Tunisie | S20: Région - Amérique du nord | T20: Myanmar | U20: Région - Afrique | V20: Vietnam
A21: Produit Test 020 - Manteau / Veste | B21: Manteau / Veste | C21: 0.25 | D21: Lin | E21: 1 | F21: Région - Asie | S21: Tunisie | T21: Tunisie | U21: Région - Europe de l'Ouest | V21: Pakistan
A22: Produit Test 021 - Pantalon / Short | B22: Pantalon / Short | C22: 0.42 | D22: Viscose | E22: 1 | F22: Turquie | S22: Région - Moyen-Orient | T22: Région - Europe de l'Est | U22: Région - Amérique Latine | V22: Inde
A23: Produit Test 022 - Manteau / Veste | B23: Manteau / Veste | C23: 0.48 | D23: Coton recyclé (déchets de production) | E23: 1 | F23: Chine | S23: Maroc | T23: Inde | U23: Région - Océanie | V23: Turquie
A24: Produit Test 023 - Caleçon (tissé) | B24: Caleçon (tissé) | C24: 0.39 | D24: Polyester recyclé | E24: 1 | F24: Région - Afrique | S24: Inde | T24: Région - Asie | U24: Myanmar | V24: Région - Europe de l'Est
A25: Produit Test 024 - Jean | B25: Jean | C25: 0.83 | D25: Coton recyclé (déchets post-consommation) | E25: 0.7 | F25: Pakistan | G25: Laine nouvelle filière | H25: 0.3 | I25: Région - Europe de l'Est | S25: Région - Océanie | T25: Pays inconnu (par défaut) | U25: Cambodge | V25: Tunisie
A26: Produit Test 025 - Manteau / Veste | B26: Manteau / Veste | C26: 0.38 | D26: Laine par défaut | E26: 1 | F26: Tunisie | S26: Tunisie | T26: Région - Amérique Latine | U26: France | V26: Bangladesh
A27: Produit Test 026 - Boxer / Slip (tricoté) | B27: Boxer / Slip (tricoté) | C27: 0.33 | D27: Laine nouvelle filière | E27: 1 | F27: Pakistan | S27: Région - Moyen-Orient | T27: Vietnam | U27: Région - Amérique du nord | V27: Chine
A28: Produit Test 027 - Pantalon / Short | B28: Pantalon / Short | C28: 0.19 | D28: Polyester recyclé | E28: 0.9 | F28: Inde | G28: Acrylique | H28: 0.1 | I28: Région - Océanie | S28: Vietnam | T28: Région - Afrique | U28: Région - Asie | V28: Région - Amérique du nord
A29: Produit Test 028 - Pantalon / Short | B29: Pantalon / Short | C29: 0.26 | D29: Coton biologique | E29: 1 | F29: Myanmar | S29: Inde | T29: Région - Amérique Latine | U29: Chine | V29: Tunisie
A30: Produit Test 029 - Jupe / Robe | B30: Jupe / Robe | C30: 0.37 | D30: Laine nouvelle filière | E30: 1 | F30: Cambodge | S30: Région - Amérique Latine | T30: Bangladesh | U30: Maroc | V30: Région - Amérique Latine
A31: Produit Test 030 - Jupe / Robe | B31: Jupe / Robe | C31: 0.2 | D31: Polyester | E31: 0.51 | F31: Région - Moyen-Orient | G31: Coton | H31: 0.49 | I31: Région - Amérique Latine | S31: Pakistan | T31: Turquie | U31: Région - Moyen-Orient | V31: Région - Océanie
A32: Produit Test 031 - Boxer / Slip (tricoté) | B32: Boxer / Slip (tricoté) | C32: 0.28 | D32: Polyester recyclé | E32: 0.66 | F32: France | G32: Jute | H32: 0.34 | I32: Tunisie | S32: Région - Europe de l'Ouest | T32: Myanmar | U32: Région - Océanie | V32: France
A33: Produit Test 032 - Pull | B33: Pull | C33: 0.65 | D33: Jute | E33: 1 | F33: Bangladesh | S33: Bangladesh | T33: Région - Europe de l'Ouest | U33: Tunisie | V33: Région - Amérique du nord
A34: Produit Test 033 - Maillot de bain | B34: Maillot de bain | C34: 0.43 | D34: Laine par défaut | E34: 0.52 | F34: Région - Amérique Latine | G34: Elasthane | H34: 0.48 | I34: France | S34: Bangladesh | T34: Région - Amérique du nord | U34: Région - Moyen-Orient | V34: Région - Amérique Latine
A35: Produit Test 034 - Caleçon (tissé) | B35: Caleçon (tissé) | C35: 0.48 | D35: Elasthane | E35: 1 | F35: France | S35: Région - Amérique du nord | T35: Région - Europe de l'Est | U35: Vietnam | V35: Région - Amérique du nord
A36: Produit Test 035 - Maillot de bain | B36: Maillot de bain | C36: 0.42 | D36: Chanvre | E36: 0.72 | F36: Turquie | G36: Coton recyclé (déchets de production) | H36: 0.28 | I36: Pays inconnu (par défaut) | S36: Cambodge | T36: Région - Asie | U36: Région - Amérique Latine | V36: Région - Asie
A37: Produit Test 036 - Jean | B37: Jean | C37: 0.55 | D37: Laine nouvelle filière | E37: 1 | F37: Vietnam | S37: Inde | T37: Turquie | U37: Cambodge | V37: Région - Europe de l'Est
A38: Produit Test 037 - T-shirt / Polo | B38: T-shirt / Polo | C38: 0.24 | D38: Jute | E38: 0.9 | F38: Région - Europe de l'Ouest | G38: Coton biologique | H38: 0.1 | I38: Chine | S38: Bangladesh | T38: Région - Europe de l'Ouest | U38: Myanmar | V38: Région - Océanie
A39: Produit Test 038 - Jean | B39: Jean | C39: 0.53 | D39: Elasthane | E39: 0.69 | F39: Région - Europe de l'Ouest | G39: Viscose | H39: 0.31 | I39: France | S39: Maroc | T39: Myanmar | U39: Pakistan | V39: Région - Moyen-Orient
A40: Produit Test 039 - Jean | B40: Jean | C40: 0.81 | D40: Coton | E40: 0.52 | F40: Région - Moyen-Orient | G40: Laine par défaut | H40: 0.48 | I40: Région - Amérique du nord | S40: Maroc | T40: Région - Afrique | U40: Région - Afrique | V40: Région - Amérique Latine
...

Sheet REF_MATERIALS
A1: Nom (lisible) | B1: UUID (API)
A2: Chanvre | B2: 0c1a4654-b030-4fe1-86b7-d96ce0b85bb8
A3: Laine par défaut | B3: 1fc3e17d-5661-429d-a150-7986eae16d9d
A4: Coton recyclé (déchets post-consommation) | B4: 457e9b0d-9eda-4dca-b199-deeb0a154fa9
A5: Acrylique | B5: 49a0bec0-f9f3-42db-a514-a9dcf06a8969
A6: Coton | B6: 62a4d6fb-3276-4ba5-93a3-889ecd3bff84
A7: Laine nouvelle filière | B7: 72e29a61-52a9-4eb5-b3fc-5fb87edea041
A8: Polypropylène | B8: 73ef624d-250e-4a9a-af5d-43505b21b527
A9: Polyester recyclé | B9: 8f44c680-1263-4588-b79b-a9e4dc3d8de4
A10: Elasthane | B10: 9973088b-c929-4cc5-894a-1e4d28c161d4
A11: Polyester | B11: 9dba0e95-0c35-4f8b-9267-62ddf47d4984
A12: Jute | B12: a09b2677-2900-4417-a202-e5f9a1abcce1
... A17: Coton recyclé (déchets de production) | B17: d3d20384-88fb-4c75-ac12-c647365ac6c5

Sheet REF_PRODUCTS
A1: Nom (lisible) | B1: ID (API)
A2: Chemise | B2: chemise
A3: Jean | B3: jean
A4: Jupe / Robe | B4: jupe
A5: Manteau / Veste | B5: manteau
A6: Pantalon / Short | B6: pantalon
A7: Pull | B7: pull
A8: T-shirt / Polo | B8: tshirt
A9: Chaussettes | B9: chaussettes
A10: Caleçon (tissé) | B10: calecon
A11: Boxer / Slip (tricoté) | B11: slip
A12: Maillot de bain | B12: maillot-de-bain

Sheet REF_COUNTRIES
A1: Nom (lisible) | B1: Code ISO (API)
A2: Pays inconnu (par défaut) | B2: ---
A3: Région - Europe de l'Ouest | B3: REO
A4: Région - Europe de l'Est | B4: REE
A5: Région - Asie | B5: RAS
A6: Région - Afrique | B6: RAF
A7: Région - Moyen-Orient | B7: RME
A8: Région - Amérique Latine | B8: RLA
A9: Région - Amérique du nord | B9: RNA
A10: Région - Océanie | B10: ROC
A11: Myanmar | B11: MM
A12: Bangladesh | B12: BD
... A21: Vietnam | B21: VN

Sheet API_INPUT
A1: product_name | B1: product | C1: mass | D1: mat1_id | E1: mat1_share | F1: mat1_country | G1: mat2_id | H1: mat2_share | I1: mat2_country | J1: mat3_id | K1: mat3_share | L1: mat3_country | M1: mat4_id | N1: mat4_share | O1: mat4_country | P1: mat5_id | Q1: mat5_share | R1: mat5_country | S1: countrySpinning | T1: countryFabric | U1: countryDyeing | V1: countryMaking
A2: =SAISIE!$A2 -> Produit Test 001 - Jupe / Robe | B2: =IFERROR(VLOOKUP(SAISIE!$B2,REF_PRODUCTS!$A:$B,2,FALSE),"") -> jupe | C2: =SAISIE!$C2 -> 0.39 | D2: =IFERROR(VLOOKUP(SAISIE!$D2,REF_MATERIALS!$A:$B,2,FALSE),"") -> 9dba0e95-0c35-4f8b-9267-62ddf47d4984 | E2: =SAISIE!$E2 -> 1 | F2: =IFERROR(VLOOKUP(SAISIE!$F2,REF_COUNTRIES!$A:$B,2,FALSE),"") -> --- | G2: =IFERROR(VLOOKUP(SAISIE!$G2,REF_MATERIALS!$A:$B,2,FALSE),"") | H2: =SAISIE!$H2 -> 0 | I2: =IFERROR(VLOOKUP(SAISIE!$I2,REF_COUNTRIES!$A:$B,2,FALSE),"") | J2: =IFERROR(VLOOKUP(SAISIE!$J2,REF_MATERIALS!$A:$B,2,FALSE),"") | K2: =SAISIE!$K2 -> 0 | L2: =IFERROR(VLOOKUP(SAISIE!$L2,REF_COUNTRIES!$A:$B,2,FALSE),"") | M2: =IFERROR(VLOOKUP(SAISIE!$M2,REF_MATERIALS!$A:$B,2,FALSE),"") | N2: =SAISIE!$N2 -> 0 | O2: =IFERROR(VLOOKUP(SAISIE!$O2,REF_COUNTRIES!$A:$B,2,FALSE),"") | P2: =IFERROR(VLOOKUP(SAISIE!$P2,REF_MATERIALS!$A:$B,2,FALSE),"") | Q2: =SAISIE!$Q2 -> 0 | R2: =IFERROR(VLOOKUP(SAISIE!$R2,REF_COUNTRIES!$A:$B,2,FALSE),"") | S2: =IFERROR(VLOOKUP(SAISIE!$S2,REF_COUNTRIES!$A:$B,2,FALSE),"") -> RLA | T2: =IFERROR(VLOOKUP(SAISIE!$T2,REF_COUNTRIES!$A:$B,2,FALSE),"") -> --- | U2: =IFERROR(VLOOKUP(SAISIE!$U2,REF_COUNTRIES!$A:$B,2,FALSE),"") -> ROC | V2: =IFERROR(VLOOKUP(SAISIE!$V2,REF_COUNTRIES!$A:$B,2,FALSE),"") -> RAS
A3: =SAISIE!$A3 -> Produit Test 002 - Caleçon (tissé) | B3: =IFERROR(VLOOKUP(SAISIE!$B3,REF_PRODUCTS!$A:$B,2,FALSE),"") -> calecon | C3: =SAISIE!$C3 -> 0.39 | D3: =IFERROR(VLOOKUP(SAISIE!$D3,REF_MATERIALS!$A:$B,2,FALSE),"") -> d3d20384-88fb-4c75-ac12-c647365ac6c5 | E3: =SAISIE!$E3 -> 1 | F3: =IFERROR(VLOOKUP(SAISIE!$F3,REF_COUNTRIES!$A:$B,2,FALSE),"") -> MM | G3: =IFERROR(VLOOKUP(SAISIE!$G3,REF_MATERIALS!$A:$B,2,FALSE),"") | H3: =SAISIE!$H3 -> 0 | I3: =IFERROR(VLOOKUP(SAISIE!$I3,REF_COUNTRIES!$A:$B,2,FALSE),"") | J3: =IFERROR(VLOOKUP(SAISIE!$J3,REF_MATERIALS!$A:$B,2,FALSE),"") | K3: =SAISIE!$K3 -> 0 | L3: =IFERROR(VLOOKUP(SAISIE!$L3,REF_COUNTRIES!$A:$B,2,FALSE),"") | M3: =IFERROR(VLOOKUP(SAISIE!$M3,REF_MATERIALS!$A:$B,2,FALSE),"") | N3: =SAISIE!$N3 -> 0 | O3: =IFERROR(VLOOKUP(SAISIE!$O3,REF_COUNTRIES!$A:$B,2,FALSE),"") | P3: =IFERROR(VLOOKUP(SAISIE!$P3,REF_MATERIALS!$A:$B,2,FALSE),"") | Q3: =SAISIE!$Q3 -> 0 | R3: =IFERROR(VLOOKUP(SAISIE!$R3,REF_COUNTRIES!$A:$B,2,FALSE),"") | S3: =IFERROR(VLOOKUP(SAISIE!$S3,REF_COUNTRIES!$A:$B,2,FALSE),"") -> FR | T3: =IFERROR(VLOOKUP(SAISIE!$T3,REF_COUNTRIES!$A:$B,2,FALSE),"") -> KH | U3: =IFERROR(VLOOKUP(SAISIE!$U3,REF_COUNTRIES!$A:$B,2,FALSE),"") -> VN | V3: =IFERROR(VLOOKUP(SAISIE!$V3,REF_COUNTRIES!$A:$B,2,FALSE),"") -> ROC
A4: =SAISIE!$A4 -> Produit Test 003 - Chaussettes | B4: =IFERROR(VLOOKUP(SAISIE!$B4,REF_PRODUCTS!$A:$B,2,FALSE),"") -> chaussettes | C4: =SAISIE!$C4 -> 0.1 | D4: =IFERROR(VLOOKUP(SAISIE!$D4,REF_MATERIALS!$A:$B,2,FALSE),"") -> c087d394-5901-4b03-ba7a-7d4b0db0490c | E4: =SAISIE!$E4 -> 1 | F4: =IFERROR(VLOOKUP(SAISIE!$F4,REF_COUNTRIES!$A:$B,2,FALSE),"") -> IN | G4: =IFERROR(VLOOKUP(SAISIE!$G4,REF_MATERIALS!$A:$B,2,FALSE),"") | H4: =SAISIE!$H4 -> 0 | I4: =IFERROR(VLOOKUP(SAISIE!$I4,REF_COUNTRIES!$A:$B,2,FALSE),"") | J4: =IFERROR(VLOOKUP(SAISIE!$J4,REF_MATERIALS!$A:$B,2,FALSE),"") | K4: =SAISIE!$K4 -> 0 | L4: =IFERROR(VLOOKUP(SAISIE!$L4,REF_COUNTRIES!$A:$B,2,FALSE),"") | M4: =IFERROR(VLOOKUP(SAISIE!$M4,REF_MATERIALS!$A:$B,2,FALSE),"") | N4: =SAISIE!$N4 -> 0 | O4: =IFERROR(VLOOKUP(SAISIE!$O4,REF_COUNTRIES!$A:$B,2,FALSE),"") | P4: =IFERROR(VLOOKUP(SAISIE!$P4,REF_MATERIALS!$A:$B,2,FALSE),"") | Q4: =SAISIE!$Q4 -> 0 | R4: =IFERROR(VLOOKUP(SAISIE!$R4,REF_COUNTRIES!$A:$B,2,FALSE),"") | S4: =IFERROR(VLOOKUP(SAISIE!$S4,REF_COUNTRIES!$A:$B,2,FALSE),"") -> ROC | T4: =IFERROR(VLOOKUP(SAISIE!$T4,REF_COUNTRIES!$A:$B,2,FALSE),"") -> RAF | U4: =IFERROR(VLOOKUP(SAISIE!$U4,REF_COUNTRIES!$A:$B,2,FALSE),"") -> MA | V4: =IFERROR(VLOOKUP(SAISIE!$V4,REF_COUNTRIES!$A:$B,2,FALSE),"") -> FR
A5: =SAISIE!$A5 -> Produit Test 004 - T-shirt / Polo | B5: =IFERROR(VLOOKUP(SAISIE!$B5,REF_PRODUCTS!$A:$B,2,FALSE),"") -> tshirt | C5: =SAISIE!$C5 -> 0.19 | D5: =IFERROR(VLOOKUP(SAISIE!$D5,REF_MATERIALS!$A:$B,2,FALSE),"") -> 0c1a4654-b030-4fe1-86b7-d96ce0b85bb8 | E5: =SAISIE!$E5 -> 0.54 | F5: =IFERROR(VLOOKUP(SAISIE!$F5,REF_COUNTRIES!$A:$B,2,FALSE),"") -> KH | G5: =IFERROR(VLOOKUP(SAISIE!$G5,REF_MATERIALS!$A:$B,2,FALSE),"") -> 9dba0e95-0c35-4f8b-9267-62ddf47d4984 | H5: =SAISIE!$H5 -> 0.46 | I5: =IFERROR(VLOOKUP(SAISIE!$I5,REF_COUNTRIES!$A:$B,2,FALSE),"") -> MM | J5: =IFERROR(VLOOKUP(SAISIE!$J5,REF_MATERIALS!$A:$B,2,FALSE),"") | K5: =SAISIE!$K5 -> 0 | L5: =IFERROR(VLOOKUP(SAISIE!$L5,REF_COUNTRIES!$A:$B,2,FALSE),"") | M5: =IFERROR(VLOOKUP(SAISIE!$M5,REF_MATERIALS!$A:$B,2,FALSE),"") | N5: =SAISIE!$N5 -> 0 | O5: =IFERROR(VLOOKUP(SAISIE!$O5,REF_COUNTRIES!$A:$B,2,FALSE),"") | P5: =IFERROR(VLOOKUP(SAISIE!$P5,REF_MATERIALS!$A:$B,2,FALSE),"") | Q5: =SAISIE!$Q5 -> 0 | R5: =IFERROR(VLOOKUP(SAISIE!$R5,REF_COUNTRIES!$A:$B,2,FALSE),"") | S5: =IFERROR(VLOOKUP(SAISIE!$S5,REF_COUNTRIES!$A:$B,2,FALSE),"") -> ROC | T5: =IFERROR(VLOOKUP(SAISIE!$T5,REF_COUNTRIES!$A:$B,2,FALSE),"") -> TN | U5: =IFERROR(VLOOKUP(SAISIE!$U5,REF_COUNTRIES!$A:$B,2,FALSE),"") -> RLA | V5: =IFERROR(VLOOKUP(SAISIE!$V5,REF_COUNTRIES!$A:$B,2,FALSE),"") -> RME
A6: =SAISIE!$A6 -> Produit Test 005 - Jean | B6: =IFERROR(VLOOKUP(SAISIE!$B6,REF_PRODUCTS!$A:$B,2,FALSE),"") -> jean | C6: =SAISIE!$C6 -> 0.7 | D6: =IFERROR(VLOOKUP(SAISIE!$D6,REF_MATERIALS!$A:$B,2,FALSE),"") -> a52e486c-b67e-40af-8337-e8143cbf9076 | E6: =SAISIE!$E6 -> 1 | F6: =IFERROR(VLOOKUP(SAISIE!$F6,REF_COUNTRIES!$A:$B,2,FALSE),"") -> BD | G6: =IFERROR(VLOOKUP(SAISIE!$G6,REF_MATERIALS!$A:$B,2,FALSE),"") | H6: =SAISIE!$H6 -> 0 | I6: =IFERROR(VLOOKUP(SAISIE!$I6,REF_COUNTRIES!$A:$B,2,FALSE),"") | J6: =IFERROR(VLOOKUP(SAISIE!$J6,REF_MATERIALS!$A:$B,2,FALSE),"") | K6: =SAISIE!$K6 -> 0 | L6: =IFERROR(VLOOKUP(SAISIE!$L6,REF_COUNTRIES!$A:$B,2,FALSE),"") | M6: =IFERROR(VLOOKUP(SAISIE!$M6,REF_MATERIALS!$A:$B,2,FALSE),"") | N6: =SAISIE!$N6 -> 0 | O6: =IFERROR(VLOOKUP(SAISIE!$O6,REF_COUNTRIES!$A:$B,2,FALSE),"") | P6: =IFERROR(VLOOKUP(SAISIE!$P6,REF_MATERIALS!$A:$B,2,FALSE),"") | Q6: =SAISIE!$Q6 -> 0 | R6: =IFERROR(VLOOKUP(SAISIE!$R6,REF_COUNTRIES!$A:$B,2,FALSE),"") | S6: =IFERROR(VLOOKUP(SAISIE!$S6,REF_COUNTRIES!$A:$B,2,FALSE),"") -> IN | T6: =IFERROR(VLOOKUP(SAISIE!$T6,REF_COUNTRIES!$A:$B,2,FALSE),"") -> MA | U6: =IFERROR(VLOOKUP(SAISIE!$U6,REF_COUNTRIES!$A:$B,2,FALSE),"") -> TR | V6: =IFERROR(VLOOKUP(SAISIE!$V6,REF_COUNTRIES!$A:$B,2,FALSE),"") -> TR
A7: =SAISIE!$A7 -> Produit Test 006 - T-shirt / Polo | B7: =IFERROR(VLOOKUP(SAISIE!$B7,REF_PRODUCTS!$A:$B,2,FALSE),"") -> tshirt | C7: =SAISIE!$C7 -> 0.17 | D7: =IFERROR(VLOOKUP(SAISIE!$D7,REF_MATERIALS!$A:$B,2,FALSE),"") -> 8f44c680-1263-4588-b79b-a9e4dc3d8de4 | E7: =SAISIE!$E7 -> 0.74 | F7: =IFERROR(VLOOKUP(SAISIE!$F7,REF_COUNTRIES!$A:$B,2,FALSE),"") -> RLA | G7: =IFERROR(VLOOKUP(SAISIE!$G7,REF_MATERIALS!$A:$B,2,FALSE),"") -> 457e9b0d-9eda-4dca-b199-deeb0a154fa9 | H7: =SAISIE!$H7 -> 0.26 | I7: =IFERROR(VLOOKUP(SAISIE!$I7,REF_COUNTRIES!$A:$B,2,FALSE),"") -> ROC | J7: =IFERROR(VLOOKUP(SAISIE!$J7,REF_MATERIALS!$A:$B,2,FALSE),"") | K7: =SAISIE!$K7 -> 0 | L7: =IFERROR(VLOOKUP(SAISIE!$L7,REF_COUNTRIES!$A:$B,2,FALSE),"") | M7: =IFERROR(VLOOKUP(SAISIE!$M7,REF_MATERIALS!$A:$B,2,FALSE),"") | N7: =SAISIE!$N7 -> 0 | O7: =IFERROR(VLOOKUP(SAISIE!$O7,REF_COUNTRIES!$A:$B,2,FALSE),"") | P7: =IFERROR(VLOOKUP(SAISIE!$P7,REF_MATERIALS!$A:$B,2,FALSE),"") | Q7: =SAISIE!$Q7 -> 0 | R7: =IFERROR(VLOOKUP(SAISIE!$R7,REF_COUNTRIES!$A:$B,2,FALSE),"") | S7: =IFERROR(VLOOKUP(SAISIE!$S7,REF_COUNTRIES!$A:$B,2,FALSE),"") -> KH | T7: =IFERROR(VLOOKUP(SAISIE!$T7,REF_COUNTRIES!$A:$B,2,FALSE),"") -> ROC | U7: =IFERROR(VLOOKUP(SAISIE!$U7,REF_COUNTRIES!$A:$B,2,FALSE),"") -> FR | V7: =IFERROR(VLOOKUP(SAISIE!$V7,REF_COUNTRIES!$A:$B,2,FALSE),"") -> RNA
A8: =SAISIE!$A8 -> Produit Test 007 - Maillot de bain | B8: =IFERROR(VLOOKUP(SAISIE!$B8,REF_PRODUCTS!$A:$B,2,FALSE),"") -> maillot-de-bain | C8: =SAISIE!$C8 -> 0.19 | D8: =IFERROR(VLOOKUP(SAISIE!$D8,REF_MATERIALS!$A:$B,2,FALSE),"") -> 73ef624d-250e-4a9a-af5d-43505b21b527 | E8: =SAISIE!$E8 -> 0.56 | F8: =IFERROR(VLOOKUP(SAISIE!$F8,REF_COUNTRIES!$A:$B,2,FALSE),"") -> RNA | G8: =IFERROR(VLOOKUP(SAISIE!$G8,REF_MATERIALS!$A:$B,2,FALSE),"") -> 62a4d6fb-3276-4ba5-93a3-889ecd3bff84 | H8: =SAISIE!$H8 -> 0.44 | I8: =IFERROR(VLOOKUP(SAISIE!$I8,REF_COUNTRIES!$A:$B,2,FALSE),"") -> KH | J8: =IFERROR(VLOOKUP(SAISIE!$J8,REF_MATERIALS!$A:$B,2,FALSE),"") | K8: =SAISIE!$K8 -> 0 | L8: =IFERROR(VLOOKUP(SAISIE!$L8,REF_COUNTRIES!$A:$B,2,FALSE),"") | M8: =IFERROR(VLOOKUP(SAISIE!$M8,REF_MATERIALS!$A:$B,2,FALSE),"") | N8: =SAISIE!$N8 -> 0 | O8: =IFERROR(VLOOKUP(SAISIE!$O8,REF_COUNTRIES!$A:$B,2,FALSE),"") | P8: =IFERROR(VLOOKUP(SAISIE!$P8,REF_MATERIALS!$A:$B,2,FALSE),"") | Q8: =SAISIE!$Q8 -> 0 | R8: =IFERROR(VLOOKUP(SAISIE!$R8,REF_COUNTRIES!$A:$B,2,FALSE),"") | S8: =IFERROR(VLOOKUP(SAISIE!$S8,REF_COUNTRIES!$A:$B,2,FALSE),"") -> TR | T8: =IFERROR(VLOOKUP(SAISIE!$T8,REF_COUNTRIES!$A:$B,2,FALSE),"") -> RAF | U8: =IFERROR(VLOOKUP(SAISIE!$U8,REF_COUNTRIES!$A:$B,2,FALSE),"") -> KH | V8: =IFERROR(VLOOKUP(SAISIE!$V8,REF_COUNTRIES!$A:$B,2,FALSE),"") -> TN
A9: =SAISIE!$A9 -> Produit Test 008 - Caleçon (tissé) | B9: =IFERROR(VLOOKUP(SAISIE!$B9,REF_PRODUCTS!$A:$B,2,FALSE),"") -> calecon | C9: =SAISIE!$C9 -> 0.48 | D9: =IFERROR(VLOOKUP(SAISIE!$D9,REF_MATERIALS!$A:$B,2,FALSE),"") -> 457e9b0d-9eda-4dca-b199-deeb0a154fa9 | E9: =SAISIE!$E9 -> 0.89 | F9: =IFERROR(VLOOKUP(SAISIE!$F9,REF_COUNTRIES!$A:$B,2,FALSE),"") -> RNA | G9: =IFERROR(VLOOKUP(SAISIE!$G9,REF_MATERIALS!$A:$B,2,FALSE),"") -> a52e486c-b67e-40af-8337-e8143cbf9076 | H9: =SAISIE!$H9 -> 0.11 | I9: =IFERROR(VLOOKUP(SAISIE!$I9,REF_COUNTRIES!$A:$B,2,FALSE),"") -> CN | J9: =IFERROR(VLOOKUP(SAISIE!$J9,REF_MATERIALS!$A:$B,2,FALSE),"") | K9: =SAISIE!$K9 -> 0 | L9: =IFERROR(VLOOKUP(SAISIE!$L9,REF_COUNTRIES!$A:$B,2,FALSE),"") | M9: =IFERROR(VLOOKUP(SAISIE!$M9,REF_MATERIALS!$A:$B,2,FALSE),"") | N9: =SAISIE!$N9 -> 0 | O9: =IFERROR(VLOOKUP(SAISIE!$O9,REF_COUNTRIES!$A:$B,2,FALSE),"") | P9: =IFERROR(VLOOKUP(SAISIE!$P9,REF_MATERIALS!$A:$B,2,FALSE),"") | Q9: =SAISIE!$Q9 -> 0 | R9: =IFERROR(VLOOKUP(SAISIE!$R9,REF_COUNTRIES!$A:$B,2,FALSE),"") | S9: =IFERROR(VLOOKUP(SAISIE!$S9,REF_COUNTRIES!$A:$B,2,FALSE),"") -> PK | T9: =IFERROR(VLOOKUP(SAISIE!$T9,REF_COUNTRIES!$A:$B,2,FALSE),"") -> RLA | U9: =IFERROR(VLOOKUP(SAISIE!$U9,REF_COUNTRIES!$A:$B,2,FALSE),"") -> MM | V9: =IFERROR(VLOOKUP(SAISIE!$V9,REF_COUNTRIES!$A:$B,2,FALSE),"") -> VN
A10: =SAISIE!$A10 -> Produit Test 009 - Manteau / Veste | B10: =IFERROR(VLOOKUP(SAISIE!$B10,REF_PRODUCTS!$A:$B,2,FALSE),"") -> manteau | C10: =SAISIE!$C10 -> 0.2 | D10: =IFERROR(VLOOKUP(SAISIE!$D10,REF_MATERIALS!$A:$B,2,FALSE),"") -> 8f44c680-1263-4588-b79b-a9e4dc3d8de4 | E10: =SAISIE!$E10 -> 1 | F10: =IFERROR(VLOOKUP(SAISIE!$F10,REF_COUNTRIES!$A:$B,2,FALSE),"") -> FR | G10: =IFERROR(VLOOKUP(SAISIE!$G10,REF_MATERIALS!$A:$B,2,FALSE),"") | H10: =SAISIE!$H10 -> 0 | I10: =IFERROR(VLOOKUP(SAISIE!$I10,REF_COUNTRIES!$A:$B,2,FALSE),"") | J10: =IFERROR(VLOOKUP(SAISIE!$J10,REF_MATERIALS!$A:$B,2,FALSE),"") | K10: =SAISIE!$K10 -> 0 | L10: =IFERROR(VLOOKUP(SAISIE!$L10,REF_COUNTRIES!$A:$B,2,FALSE),"") | M10: =IFERROR(VLOOKUP(SAISIE!$M10,REF_MATERIALS!$A:$B,2,FALSE),"") | N10: =SAISIE!$N10 -> 0 | O10: =IFERROR(VLOOKUP(SAISIE!$O10,REF_COUNTRIES!$A:$B,2,FALSE),"") | P10: =IFERROR(VLOOKUP(SAISIE!$P10,REF_MATERIALS!$A:$B,2,FALSE),"") | Q10: =SAISIE!$Q10 -> 0 | R10: =IFERROR(VLOOKUP(SAISIE!$R10,REF_COUNTRIES!$A:$B,2,FALSE),"") | S10: =IFERROR(VLOOKUP(SAISIE!$S10,REF_COUNTRIES!$A:$B,2,FALSE),"") -> BD | T10: =IFERROR(VLOOKUP(SAISIE!$T10,REF_COUNTRIES!$A:$B,2,FALSE),"") -> ROC | U10: =IFERROR(VLOOKUP(SAISIE!$U10,REF_COUNTRIES!$A:$B,2,FALSE),"") -> TR | V10: =IFERROR(VLOOKUP(SAISIE!$V10,REF_COUNTRIES!$A:$B,2,FALSE),"") -> REO
A11: =SAISIE!$A11 -> Produit Test 010 - Manteau / Veste | B11: =IFERROR(VLOOKUP(SAISIE!$B11,REF_PRODUCTS!$A:$B,2,FALSE),"") -> manteau | C11: =SAISIE!$C11 -> 0.34 | D11: =IFERROR(VLOOKUP(SAISIE!$D11,REF_MATERIALS!$A:$B,2,FALSE),"") -> 9dba0e95-0c35-4f8b-9267-62ddf47d4984 | E11: =SAISIE!$E11 -> 1 | F11: =IFERROR(VLOOKUP(SAISIE!$F11,REF_COUNTRIES!$A:$B,2,FALSE),"") -> REO | G11: =IFERROR(VLOOKUP(SAISIE!$G11,REF_MATERIALS!$A:$B,2,FALSE),"") | H11: =SAISIE!$H11 -> 0 | I11: =IFERROR(VLOOKUP(SAISIE!$I11,REF_COUNTRIES!$A:$B,2,FALSE),"") | J11: =IFERROR(VLOOKUP(SAISIE!$J11,REF_MATERIALS!$A:$B,2,FALSE),"") | K11: =SAISIE!$K11 -> 0 | L11: =IFERROR(VLOOKUP(SAISIE!$L11,REF_COUNTRIES!$A:$B,2,FALSE),"") | M11: =IFERROR(VLOOKUP(SAISIE!$M11,REF_MATERIALS!$A:$B,2,FALSE),"") | N11: =SAISIE!$N11 -> 0 | O11: =IFERROR(VLOOKUP(SAISIE!$O11,REF_COUNTRIES!$A:$B,2,FALSE),"") | P11: =IFERROR(VLOOKUP(SAISIE!$P11,REF_MATERIALS!$A:$B,2,FALSE),"") | Q11: =SAISIE!$Q11 -> 0 | R11: =IFERROR(VLOOKUP(SAISIE!$R11,REF_COUNTRIES!$A:$B,2,FALSE),"") | S11: =IFERROR(VLOOKUP(SAISIE!$S11,REF_COUNTRIES!$A:$B,2,FALSE),"") -> VN | T11: =IFERROR(VLOOKUP(SAISIE!$T11,REF_COUNTRIES!$A:$B,2,FALSE),"") -> MM | U11: =IFERROR(VLOOKUP(SAISIE!$U11,REF_COUNTRIES!$A:$B,2,FALSE),"") -> CN | V11: =IFERROR(VLOOKUP(SAISIE!$V11,REF_COUNTRIES!$A:$B,2,FALSE),"") -> RLA
A12: =SAISIE!$A12 -> Produit Test 011 - Pull | B12: =IFERROR(VLOOKUP(SAISIE!$B12,REF_PRODUCTS!$A:$B,2,FALSE),"") -> pull | C12: =SAISIE!$C12 -> 0.3 | D12: =IFERROR(VLOOKUP(SAISIE!$D12,REF_MATERIALS!$A:$B,2,FALSE),"") -> a09b2677-2900-4417-a202-e5f9a1abcce1 | E12: =SAISIE!$E12 -> 1 | F12: =IFERROR(VLOOKUP(SAISIE!$F12,REF_COUNTRIES!$A:$B,2,FALSE),"") -> --- | G12: =IFERROR(VLOOKUP(SAISIE!$G12,REF_MATERIALS!$A:$B,2,FALSE),"") | H12: =SAISIE!$H12 -> 0 | I12: =IFERROR(VLOOKUP(SAISIE!$I12,REF_COUNTRIES!$A:$B,2,FALSE),"") | J12: =IFERROR(VLOOKUP(SAISIE!$J12,REF_MATERIALS!$A:$B,2,FALSE),"") | K12: =SAISIE!$K12 -> 0 | L12: =IFERROR(VLOOKUP(SAISIE!$L12,REF_COUNTRIES!$A:$B,2,FALSE),"") | M12: =IFERROR(VLOOKUP(SAISIE!$M12,REF_MATERIALS!$A:$B,2,FALSE),"") | N12: =SAISIE!$N12 -> 0 | O12: =IFERROR(VLOOKUP(SAISIE!$O12,REF_COUNTRIES!$A:$B,2,FALSE),"") | P12: =IFERROR(VLOOKUP(SAISIE!$P12,REF_MATERIALS!$A:$B,2,FALSE),"") | Q12: =SAISIE!$Q12 -> 0 | R12: =IFERROR(VLOOKUP(SAISIE!$R12,REF_COUNTRIES!$A:$B,2,FALSE),"") | S12: =IFERROR(VLOOKUP(SAISIE!$S12,REF_COUNTRIES!$A:$B,2,FALSE),"") -> ROC | T12: =IFERROR(VLOOKUP(SAISIE!$T12,REF_COUNTRIES!$A:$B,2,FALSE),"") -> RME | U12: =IFERROR(VLOOKUP(SAISIE!$U12,REF_COUNTRIES!$A:$B,2,FALSE),"") -> RAS | V12: =IFERROR(VLOOKUP(SAISIE!$V12,REF_COUNTRIES!$A:$B,2,FALSE),"") -> PK
A13: =SAISIE!$A13 -> Produit Test 012 - Maillot de bain | B13: =IFERROR(VLOOKUP(SAISIE!$B13,REF_PRODUCTS!$A:$B,2,FALSE),"") -> maillot-de-bain | C13: =SAISIE!$C13 -> 0.22 | D13: =IFERROR(VLOOKUP(SAISIE!$D13,REF_MATERIALS!$A:$B,2,FALSE),"") -> 72e29a61-52a9-4eb5-b3fc-5fb87edea041 | E13: =SAISIE!$E13 -> 1 | F13: =IFERROR(VLOOKUP(SAISIE!$F13,REF_COUNTRIES!$A:$B,2,FALSE),"") -> KH | G13: =IFERROR(VLOOKUP(SAISIE!$G13,REF_MATERIALS!$A:$B,2,FALSE),"") | H13: =SAISIE!$H13 -> 0 | I13: =IFERROR(VLOOKUP(SAISIE!$I13,REF_COUNTRIES!$A:$B,2,FALSE),"") | J13: =IFERROR(VLOOKUP(SAISIE!$J13,REF_MATERIALS!$A:$B,2,FALSE),"") | K13: =SAISIE!$K13 -> 0 | L13: =IFERROR(VLOOKUP(SAISIE!$L13,REF_COUNTRIES!$A:$B,2,FALSE),"") | M13: =IFERROR(VLOOKUP(SAISIE!$M13,REF_MATERIALS!$A:$B,2,FALSE),"") | N13: =SAISIE!$N13 -> 0 | O13: =IFERROR(VLOOKUP(SAISIE!$O13,REF_COUNTRIES!$A:$B,2,FALSE),"") | P13: =IFERROR(VLOOKUP(SAISIE!$P13,REF_MATERIALS!$A:$B,2,FALSE),"") | Q13: =SAISIE!$Q13 -> 0 | R13: =IFERROR(VLOOKUP(SAISIE!$R13,REF_COUNTRIES!$A:$B,2,FALSE),"") | S13: =IFERROR(VLOOKUP(SAISIE!$S13,REF_COUNTRIES!$A:$B,2,FALSE),"") -> TN | T13: =IFERROR(VLOOKUP(SAISIE!$T13,REF_COUNTRIES!$A:$B,2,FALSE),"") -> RNA | U13: =IFERROR(VLOOKUP(SAISIE!$U13,REF_COUNTRIES!$A:$B,2,FALSE),"") -> RME | V13: =IFERROR(VLOOKUP(SAISIE!$V13,REF_COUNTRIES!$A:$B,2,FALSE),"") -> RAS
... A101: =SAISIE!$A101 -> Produit Test 100 - T-shirt / Polo | B101: =IFERROR(VLOOKUP(SAISIE!$B101,REF_PRODUCTS!$A:$B,2,FALSE),"") -> tshirt | C101: =SAISIE!$C101 -> 0.16 | D101: =IFERROR(VLOOKUP(SAISIE!$D101,REF_MATERIALS!$A:$B,2,FALSE),"") -> 62a4d6fb-3276-4ba5-93a3-889ecd3bff84 | E101: =SAISIE!$E101 -> 1 | F101: =IFERROR(VLOOKUP(SAISIE!$F101,REF_COUNTRIES!$A:$B,2,FALSE),"") -> RAF | G101: =IFERROR(VLOOKUP(SAISIE!$G101,REF_MATERIALS!$A:$B,2,FALSE),"") | H101: =SAISIE!$H101 -> 0 | I101: =IFERROR(VLOOKUP(SAISIE!$I101,REF_COUNTRIES!$A:$B,2,FALSE),"") | J101: =IFERROR(VLOOKUP(SAISIE!$J101,REF_MATERIALS!$A:$B,2,FALSE),"") | K101: =SAISIE!$K101 -> 0 | L101: =IFERROR(VLOOKUP(SAISIE!$L101,REF_COUNTRIES!$A:$B,2,FALSE),"") | M101: =IFERROR(VLOOKUP(SAISIE!$M101,REF_MATERIALS!$A:$B,2,FALSE),"") | N101: =SAISIE!$N101 -> 0 | O101: =IFERROR(VLOOKUP(SAISIE!$O101,REF_COUNTRIES!$A:$B,2,FALSE),"") | P101: =IFERROR(VLOOKUP(SAISIE!$P101,REF_MATERIALS!$A:$B,2,FALSE),"") | Q101: =SAISIE!$Q101 -> 0 | R101: =IFERROR(VLOOKUP(SAISIE!$R101,REF_COUNTRIES!$A:$B,2,FALSE),"") | S101: =IFERROR(VLOOKUP(SAISIE!$S101,REF_COUNTRIES!$A:$B,2,FALSE),"") -> KH | T101: =IFERROR(VLOOKUP(SAISIE!$T101,REF_COUNTRIES!$A:$B,2,FALSE),"") -> RAS | U101: =IFERROR(VLOOKUP(SAISIE!$U101,REF_COUNTRIES!$A:$B,2,FALSE),"") -> RAS | V101: =IFERROR(VLOOKUP(SAISIE!$V101,REF_COUNTRIES!$A:$B,2,FALSE),"") -> BD
